Traceback (most recent call last):
  File "/Users/guy/miniconda3/lib/python3.8/site-packages/jupyter_cache/executors/utils.py", line 51, in single_nb_execution
    executenb(
  File "/Users/guy/miniconda3/lib/python3.8/site-packages/nbclient/client.py", line 1087, in execute
    return NotebookClient(nb=nb, resources=resources, km=km, **kwargs).execute()
  File "/Users/guy/miniconda3/lib/python3.8/site-packages/nbclient/util.py", line 74, in wrapped
    return just_run(coro(*args, **kwargs))
  File "/Users/guy/miniconda3/lib/python3.8/site-packages/nbclient/util.py", line 53, in just_run
    return loop.run_until_complete(coro)
  File "/Users/guy/miniconda3/lib/python3.8/asyncio/base_events.py", line 616, in run_until_complete
    return future.result()
  File "/Users/guy/miniconda3/lib/python3.8/site-packages/nbclient/client.py", line 540, in async_execute
    await self.async_execute_cell(
  File "/Users/guy/miniconda3/lib/python3.8/site-packages/nbclient/client.py", line 832, in async_execute_cell
    self._check_raise_for_error(cell, exec_reply)
  File "/Users/guy/miniconda3/lib/python3.8/site-packages/nbclient/client.py", line 740, in _check_raise_for_error
    raise CellExecutionError.from_cell_and_msg(cell, exec_reply['content'])
nbclient.exceptions.CellExecutionError: An error occurred while executing the following cell:
------------------
response = requests.get(url).json()
api_dataset = response

#looping through and putting data to the list api_dataset
for page in range (1, 20):
    response = requests.get(url + f"&page={page}").json()
    api_dataset.extend(response)

pmap_data = pd.json_normalize(api_dataset)
------------------

[0;31m---------------------------------------------------------------------------[0m
[0;31mSysCallError[0m                              Traceback (most recent call last)
[0;32m~/miniconda3/lib/python3.8/site-packages/urllib3/contrib/pyopenssl.py[0m in [0;36mwrap_socket[0;34m(self, sock, server_side, do_handshake_on_connect, suppress_ragged_eofs, server_hostname)[0m
[1;32m    484[0m             [0;32mtry[0m[0;34m:[0m[0;34m[0m[0;34m[0m[0m
[0;32m--> 485[0;31m                 [0mcnx[0m[0;34m.[0m[0mdo_handshake[0m[0;34m([0m[0;34m)[0m[0;34m[0m[0;34m[0m[0m
[0m[1;32m    486[0m             [0;32mexcept[0m [0mOpenSSL[0m[0;34m.[0m[0mSSL[0m[0;34m.[0m[0mWantReadError[0m[0;34m:[0m[0;34m[0m[0;34m[0m[0m

[0;32m~/miniconda3/lib/python3.8/site-packages/OpenSSL/SSL.py[0m in [0;36mdo_handshake[0;34m(self)[0m
[1;32m   1933[0m         [0mresult[0m [0;34m=[0m [0m_lib[0m[0;34m.[0m[0mSSL_do_handshake[0m[0;34m([0m[0mself[0m[0;34m.[0m[0m_ssl[0m[0;34m)[0m[0;34m[0m[0;34m[0m[0m
[0;32m-> 1934[0;31m         [0mself[0m[0;34m.[0m[0m_raise_ssl_error[0m[0;34m([0m[0mself[0m[0;34m.[0m[0m_ssl[0m[0;34m,[0m [0mresult[0m[0;34m)[0m[0;34m[0m[0;34m[0m[0m
[0m[1;32m   1935[0m [0;34m[0m[0m

[0;32m~/miniconda3/lib/python3.8/site-packages/OpenSSL/SSL.py[0m in [0;36m_raise_ssl_error[0;34m(self, ssl, result)[0m
[1;32m   1662[0m                     [0;32mif[0m [0merrno[0m [0;34m!=[0m [0;36m0[0m[0;34m:[0m[0;34m[0m[0;34m[0m[0m
[0;32m-> 1663[0;31m                         [0;32mraise[0m [0mSysCallError[0m[0;34m([0m[0merrno[0m[0;34m,[0m [0merrorcode[0m[0;34m.[0m[0mget[0m[0;34m([0m[0merrno[0m[0;34m)[0m[0;34m)[0m[0;34m[0m[0;34m[0m[0m
[0m[1;32m   1664[0m                 [0;32mraise[0m [0mSysCallError[0m[0;34m([0m[0;34m-[0m[0;36m1[0m[0;34m,[0m [0;34m"Unexpected EOF"[0m[0;34m)[0m[0;34m[0m[0;34m[0m[0m

[0;31mSysCallError[0m: (54, 'ECONNRESET')

During handling of the above exception, another exception occurred:

[0;31mSSLError[0m                                  Traceback (most recent call last)
[0;32m~/miniconda3/lib/python3.8/site-packages/urllib3/connectionpool.py[0m in [0;36murlopen[0;34m(self, method, url, body, headers, retries, redirect, assert_same_host, timeout, pool_timeout, release_conn, chunked, body_pos, **response_kw)[0m
[1;32m    664[0m             [0;31m# Make the request on the httplib connection object.[0m[0;34m[0m[0;34m[0m[0;34m[0m[0m
[0;32m--> 665[0;31m             httplib_response = self._make_request(
[0m[1;32m    666[0m                 [0mconn[0m[0;34m,[0m[0;34m[0m[0;34m[0m[0m

[0;32m~/miniconda3/lib/python3.8/site-packages/urllib3/connectionpool.py[0m in [0;36m_make_request[0;34m(self, conn, method, url, timeout, chunked, **httplib_request_kw)[0m
[1;32m    375[0m         [0;32mtry[0m[0;34m:[0m[0;34m[0m[0;34m[0m[0m
[0;32m--> 376[0;31m             [0mself[0m[0;34m.[0m[0m_validate_conn[0m[0;34m([0m[0mconn[0m[0;34m)[0m[0;34m[0m[0;34m[0m[0m
[0m[1;32m    377[0m         [0;32mexcept[0m [0;34m([0m[0mSocketTimeout[0m[0;34m,[0m [0mBaseSSLError[0m[0;34m)[0m [0;32mas[0m [0me[0m[0;34m:[0m[0;34m[0m[0;34m[0m[0m

[0;32m~/miniconda3/lib/python3.8/site-packages/urllib3/connectionpool.py[0m in [0;36m_validate_conn[0;34m(self, conn)[0m
[1;32m    993[0m         [0;32mif[0m [0;32mnot[0m [0mgetattr[0m[0;34m([0m[0mconn[0m[0;34m,[0m [0;34m"sock"[0m[0;34m,[0m [0;32mNone[0m[0;34m)[0m[0;34m:[0m  [0;31m# AppEngine might not have  `.sock`[0m[0;34m[0m[0;34m[0m[0m
[0;32m--> 994[0;31m             [0mconn[0m[0;34m.[0m[0mconnect[0m[0;34m([0m[0;34m)[0m[0;34m[0m[0;34m[0m[0m
[0m[1;32m    995[0m [0;34m[0m[0m

[0;32m~/miniconda3/lib/python3.8/site-packages/urllib3/connection.py[0m in [0;36mconnect[0;34m(self)[0m
[1;32m    351[0m [0;34m[0m[0m
[0;32m--> 352[0;31m         self.sock = ssl_wrap_socket(
[0m[1;32m    353[0m             [0msock[0m[0;34m=[0m[0mconn[0m[0;34m,[0m[0;34m[0m[0;34m[0m[0m

[0;32m~/miniconda3/lib/python3.8/site-packages/urllib3/util/ssl_.py[0m in [0;36mssl_wrap_socket[0;34m(sock, keyfile, certfile, cert_reqs, ca_certs, server_hostname, ssl_version, ciphers, ssl_context, ca_cert_dir, key_password)[0m
[1;32m    369[0m         [0;32mif[0m [0mHAS_SNI[0m [0;32mand[0m [0mserver_hostname[0m [0;32mis[0m [0;32mnot[0m [0;32mNone[0m[0;34m:[0m[0;34m[0m[0;34m[0m[0m
[0;32m--> 370[0;31m             [0;32mreturn[0m [0mcontext[0m[0;34m.[0m[0mwrap_socket[0m[0;34m([0m[0msock[0m[0;34m,[0m [0mserver_hostname[0m[0;34m=[0m[0mserver_hostname[0m[0;34m)[0m[0;34m[0m[0;34m[0m[0m
[0m[1;32m    371[0m [0;34m[0m[0m

[0;32m~/miniconda3/lib/python3.8/site-packages/urllib3/contrib/pyopenssl.py[0m in [0;36mwrap_socket[0;34m(self, sock, server_side, do_handshake_on_connect, suppress_ragged_eofs, server_hostname)[0m
[1;32m    490[0m             [0;32mexcept[0m [0mOpenSSL[0m[0;34m.[0m[0mSSL[0m[0;34m.[0m[0mError[0m [0;32mas[0m [0me[0m[0;34m:[0m[0;34m[0m[0;34m[0m[0m
[0;32m--> 491[0;31m                 [0;32mraise[0m [0mssl[0m[0;34m.[0m[0mSSLError[0m[0;34m([0m[0;34m"bad handshake: %r"[0m [0;34m%[0m [0me[0m[0;34m)[0m[0;34m[0m[0;34m[0m[0m
[0m[1;32m    492[0m             [0;32mbreak[0m[0;34m[0m[0;34m[0m[0m

[0;31mSSLError[0m: ("bad handshake: SysCallError(54, 'ECONNRESET')",)

During handling of the above exception, another exception occurred:

[0;31mMaxRetryError[0m                             Traceback (most recent call last)
[0;32m~/miniconda3/lib/python3.8/site-packages/requests/adapters.py[0m in [0;36msend[0;34m(self, request, stream, timeout, verify, cert, proxies)[0m
[1;32m    438[0m             [0;32mif[0m [0;32mnot[0m [0mchunked[0m[0;34m:[0m[0;34m[0m[0;34m[0m[0m
[0;32m--> 439[0;31m                 resp = conn.urlopen(
[0m[1;32m    440[0m                     [0mmethod[0m[0;34m=[0m[0mrequest[0m[0;34m.[0m[0mmethod[0m[0;34m,[0m[0;34m[0m[0;34m[0m[0m

[0;32m~/miniconda3/lib/python3.8/site-packages/urllib3/connectionpool.py[0m in [0;36murlopen[0;34m(self, method, url, body, headers, retries, redirect, assert_same_host, timeout, pool_timeout, release_conn, chunked, body_pos, **response_kw)[0m
[1;32m    718[0m [0;34m[0m[0m
[0;32m--> 719[0;31m             retries = retries.increment(
[0m[1;32m    720[0m                 [0mmethod[0m[0;34m,[0m [0murl[0m[0;34m,[0m [0merror[0m[0;34m=[0m[0me[0m[0;34m,[0m [0m_pool[0m[0;34m=[0m[0mself[0m[0;34m,[0m [0m_stacktrace[0m[0;34m=[0m[0msys[0m[0;34m.[0m[0mexc_info[0m[0;34m([0m[0;34m)[0m[0;34m[[0m[0;36m2[0m[0;34m][0m[0;34m[0m[0;34m[0m[0m

[0;32m~/miniconda3/lib/python3.8/site-packages/urllib3/util/retry.py[0m in [0;36mincrement[0;34m(self, method, url, response, error, _pool, _stacktrace)[0m
[1;32m    435[0m         [0;32mif[0m [0mnew_retry[0m[0;34m.[0m[0mis_exhausted[0m[0;34m([0m[0;34m)[0m[0;34m:[0m[0;34m[0m[0;34m[0m[0m
[0;32m--> 436[0;31m             [0;32mraise[0m [0mMaxRetryError[0m[0;34m([0m[0m_pool[0m[0;34m,[0m [0murl[0m[0;34m,[0m [0merror[0m [0;32mor[0m [0mResponseError[0m[0;34m([0m[0mcause[0m[0;34m)[0m[0;34m)[0m[0;34m[0m[0;34m[0m[0m
[0m[1;32m    437[0m [0;34m[0m[0m

[0;31mMaxRetryError[0m: HTTPSConnectionPool(host='api.openbrewerydb.org', port=443): Max retries exceeded with url: /breweries?per_page=50&page=10 (Caused by SSLError(SSLError("bad handshake: SysCallError(54, 'ECONNRESET')")))

During handling of the above exception, another exception occurred:

[0;31mSSLError[0m                                  Traceback (most recent call last)
[0;32m<ipython-input-4-4c3bb1d9abaa>[0m in [0;36m<module>[0;34m[0m
[1;32m      4[0m [0;31m#looping through and putting data to the list api_dataset[0m[0;34m[0m[0;34m[0m[0;34m[0m[0m
[1;32m      5[0m [0;32mfor[0m [0mpage[0m [0;32min[0m [0mrange[0m [0;34m([0m[0;36m1[0m[0;34m,[0m [0;36m20[0m[0;34m)[0m[0;34m:[0m[0;34m[0m[0;34m[0m[0m
[0;32m----> 6[0;31m     [0mresponse[0m [0;34m=[0m [0mrequests[0m[0;34m.[0m[0mget[0m[0;34m([0m[0murl[0m [0;34m+[0m [0;34mf"&page={page}"[0m[0;34m)[0m[0;34m.[0m[0mjson[0m[0;34m([0m[0;34m)[0m[0;34m[0m[0;34m[0m[0m
[0m[1;32m      7[0m     [0mapi_dataset[0m[0;34m.[0m[0mextend[0m[0;34m([0m[0mresponse[0m[0;34m)[0m[0;34m[0m[0;34m[0m[0m
[1;32m      8[0m [0;34m[0m[0m

[0;32m~/miniconda3/lib/python3.8/site-packages/requests/api.py[0m in [0;36mget[0;34m(url, params, **kwargs)[0m
[1;32m     74[0m [0;34m[0m[0m
[1;32m     75[0m     [0mkwargs[0m[0;34m.[0m[0msetdefault[0m[0;34m([0m[0;34m'allow_redirects'[0m[0;34m,[0m [0;32mTrue[0m[0;34m)[0m[0;34m[0m[0;34m[0m[0m
[0;32m---> 76[0;31m     [0;32mreturn[0m [0mrequest[0m[0;34m([0m[0;34m'get'[0m[0;34m,[0m [0murl[0m[0;34m,[0m [0mparams[0m[0;34m=[0m[0mparams[0m[0;34m,[0m [0;34m**[0m[0mkwargs[0m[0;34m)[0m[0;34m[0m[0;34m[0m[0m
[0m[1;32m     77[0m [0;34m[0m[0m
[1;32m     78[0m [0;34m[0m[0m

[0;32m~/miniconda3/lib/python3.8/site-packages/requests/api.py[0m in [0;36mrequest[0;34m(method, url, **kwargs)[0m
[1;32m     59[0m     [0;31m# cases, and look like a memory leak in others.[0m[0;34m[0m[0;34m[0m[0;34m[0m[0m
[1;32m     60[0m     [0;32mwith[0m [0msessions[0m[0;34m.[0m[0mSession[0m[0;34m([0m[0;34m)[0m [0;32mas[0m [0msession[0m[0;34m:[0m[0;34m[0m[0;34m[0m[0m
[0;32m---> 61[0;31m         [0;32mreturn[0m [0msession[0m[0;34m.[0m[0mrequest[0m[0;34m([0m[0mmethod[0m[0;34m=[0m[0mmethod[0m[0;34m,[0m [0murl[0m[0;34m=[0m[0murl[0m[0;34m,[0m [0;34m**[0m[0mkwargs[0m[0;34m)[0m[0;34m[0m[0;34m[0m[0m
[0m[1;32m     62[0m [0;34m[0m[0m
[1;32m     63[0m [0;34m[0m[0m

[0;32m~/miniconda3/lib/python3.8/site-packages/requests/sessions.py[0m in [0;36mrequest[0;34m(self, method, url, params, data, headers, cookies, files, auth, timeout, allow_redirects, proxies, hooks, stream, verify, cert, json)[0m
[1;32m    528[0m         }
[1;32m    529[0m         [0msend_kwargs[0m[0;34m.[0m[0mupdate[0m[0;34m([0m[0msettings[0m[0;34m)[0m[0;34m[0m[0;34m[0m[0m
[0;32m--> 530[0;31m         [0mresp[0m [0;34m=[0m [0mself[0m[0;34m.[0m[0msend[0m[0;34m([0m[0mprep[0m[0;34m,[0m [0;34m**[0m[0msend_kwargs[0m[0;34m)[0m[0;34m[0m[0;34m[0m[0m
[0m[1;32m    531[0m [0;34m[0m[0m
[1;32m    532[0m         [0;32mreturn[0m [0mresp[0m[0;34m[0m[0;34m[0m[0m

[0;32m~/miniconda3/lib/python3.8/site-packages/requests/sessions.py[0m in [0;36msend[0;34m(self, request, **kwargs)[0m
[1;32m    641[0m [0;34m[0m[0m
[1;32m    642[0m         [0;31m# Send the request[0m[0;34m[0m[0;34m[0m[0;34m[0m[0m
[0;32m--> 643[0;31m         [0mr[0m [0;34m=[0m [0madapter[0m[0;34m.[0m[0msend[0m[0;34m([0m[0mrequest[0m[0;34m,[0m [0;34m**[0m[0mkwargs[0m[0;34m)[0m[0;34m[0m[0;34m[0m[0m
[0m[1;32m    644[0m [0;34m[0m[0m
[1;32m    645[0m         [0;31m# Total elapsed time of the request (approximately)[0m[0;34m[0m[0;34m[0m[0;34m[0m[0m

[0;32m~/miniconda3/lib/python3.8/site-packages/requests/adapters.py[0m in [0;36msend[0;34m(self, request, stream, timeout, verify, cert, proxies)[0m
[1;32m    512[0m             [0;32mif[0m [0misinstance[0m[0;34m([0m[0me[0m[0;34m.[0m[0mreason[0m[0;34m,[0m [0m_SSLError[0m[0;34m)[0m[0;34m:[0m[0;34m[0m[0;34m[0m[0m
[1;32m    513[0m                 [0;31m# This branch is for urllib3 v1.22 and later.[0m[0;34m[0m[0;34m[0m[0;34m[0m[0m
[0;32m--> 514[0;31m                 [0;32mraise[0m [0mSSLError[0m[0;34m([0m[0me[0m[0;34m,[0m [0mrequest[0m[0;34m=[0m[0mrequest[0m[0;34m)[0m[0;34m[0m[0;34m[0m[0m
[0m[1;32m    515[0m [0;34m[0m[0m
[1;32m    516[0m             [0;32mraise[0m [0mConnectionError[0m[0;34m([0m[0me[0m[0;34m,[0m [0mrequest[0m[0;34m=[0m[0mrequest[0m[0;34m)[0m[0;34m[0m[0;34m[0m[0m

[0;31mSSLError[0m: HTTPSConnectionPool(host='api.openbrewerydb.org', port=443): Max retries exceeded with url: /breweries?per_page=50&page=10 (Caused by SSLError(SSLError("bad handshake: SysCallError(54, 'ECONNRESET')")))
SSLError: HTTPSConnectionPool(host='api.openbrewerydb.org', port=443): Max retries exceeded with url: /breweries?per_page=50&page=10 (Caused by SSLError(SSLError("bad handshake: SysCallError(54, 'ECONNRESET')")))

