Traceback (most recent call last):
  File "/Users/guy/miniconda3/lib/python3.8/site-packages/jupyter_cache/executors/utils.py", line 51, in single_nb_execution
    executenb(
  File "/Users/guy/miniconda3/lib/python3.8/site-packages/nbclient/client.py", line 1087, in execute
    return NotebookClient(nb=nb, resources=resources, km=km, **kwargs).execute()
  File "/Users/guy/miniconda3/lib/python3.8/site-packages/nbclient/util.py", line 74, in wrapped
    return just_run(coro(*args, **kwargs))
  File "/Users/guy/miniconda3/lib/python3.8/site-packages/nbclient/util.py", line 53, in just_run
    return loop.run_until_complete(coro)
  File "/Users/guy/miniconda3/lib/python3.8/asyncio/base_events.py", line 616, in run_until_complete
    return future.result()
  File "/Users/guy/miniconda3/lib/python3.8/site-packages/nbclient/client.py", line 540, in async_execute
    await self.async_execute_cell(
  File "/Users/guy/miniconda3/lib/python3.8/site-packages/nbclient/client.py", line 832, in async_execute_cell
    self._check_raise_for_error(cell, exec_reply)
  File "/Users/guy/miniconda3/lib/python3.8/site-packages/nbclient/client.py", line 740, in _check_raise_for_error
    raise CellExecutionError.from_cell_and_msg(cell, exec_reply['content'])
nbclient.exceptions.CellExecutionError: An error occurred while executing the following cell:
------------------
def date_convert(date_of_conversion):
    if (date_str[2] == '-') and (date_str[5] == '-'):
        date_object = pd.Timestamp(datetime.strptime(date_of_conversion, '%d-%m-%Y').date())
        return date_object
    else:
        message = 'Make sure you have entered the date in the right format (dd-mm-yyyy)'
        return message

date_object = date_convert('13-03-1996')
c.get_rates('USD', date_object)
------------------

[0;31m---------------------------------------------------------------------------[0m
[0;31mRatesNotAvailableError[0m                    Traceback (most recent call last)
[0;32m<ipython-input-9-5489e3943217>[0m in [0;36m<module>[0;34m[0m
[1;32m      8[0m [0;34m[0m[0m
[1;32m      9[0m [0mdate_object[0m [0;34m=[0m [0mdate_convert[0m[0;34m([0m[0;34m'13-03-1996'[0m[0;34m)[0m[0;34m[0m[0;34m[0m[0m
[0;32m---> 10[0;31m [0mc[0m[0;34m.[0m[0mget_rates[0m[0;34m([0m[0;34m'USD'[0m[0;34m,[0m [0mdate_object[0m[0;34m)[0m[0;34m[0m[0;34m[0m[0m
[0m
[0;32m~/miniconda3/lib/python3.8/site-packages/forex_python/converter.py[0m in [0;36mget_rates[0;34m(self, base_cur, date_obj)[0m
[1;32m     54[0m             [0mrates[0m [0;34m=[0m [0mself[0m[0;34m.[0m[0m_decode_rates[0m[0;34m([0m[0mresponse[0m[0;34m)[0m[0;34m[0m[0;34m[0m[0m
[1;32m     55[0m             [0;32mreturn[0m [0mrates[0m[0;34m[0m[0;34m[0m[0m
[0;32m---> 56[0;31m         [0;32mraise[0m [0mRatesNotAvailableError[0m[0;34m([0m[0;34m"Currency Rates Source Not Ready"[0m[0;34m)[0m[0;34m[0m[0;34m[0m[0m
[0m[1;32m     57[0m [0;34m[0m[0m
[1;32m     58[0m     [0;32mdef[0m [0mget_rate[0m[0;34m([0m[0mself[0m[0;34m,[0m [0mbase_cur[0m[0;34m,[0m [0mdest_cur[0m[0;34m,[0m [0mdate_obj[0m[0;34m=[0m[0;32mNone[0m[0;34m)[0m[0;34m:[0m[0;34m[0m[0;34m[0m[0m

[0;31mRatesNotAvailableError[0m: Currency Rates Source Not Ready
RatesNotAvailableError: Currency Rates Source Not Ready

